Failure # 1 (occurred at 2021-12-21_10-03-09)
Traceback (most recent call last):
  File "E:\anaconda\envs\logitech\lib\site-packages\ray\tune\trial_runner.py", line 739, in _process_trial
    results = self.trial_executor.fetch_result(trial)
  File "E:\anaconda\envs\logitech\lib\site-packages\ray\tune\ray_trial_executor.py", line 746, in fetch_result
    result = ray.get(trial_future[0], timeout=DEFAULT_GET_TIMEOUT)
  File "E:\anaconda\envs\logitech\lib\site-packages\ray\_private\client_mode_hook.py", line 82, in wrapper
    return func(*args, **kwargs)
  File "E:\anaconda\envs\logitech\lib\site-packages\ray\worker.py", line 1621, in get
    raise value.as_instanceof_cause()
ray.exceptions.RayTaskError: [36mray::DDPG.train()[39m (pid=30616, ip=172.22.22.53, repr=DDPG)
  File "python\ray\_raylet.pyx", line 536, in ray._raylet.execute_task
  File "python\ray\_raylet.pyx", line 486, in ray._raylet.execute_task.function_executor
  File "E:\anaconda\envs\logitech\lib\site-packages\ray\_private\function_manager.py", line 563, in actor_method_executor
    return method(__ray_actor, *args, **kwargs)
  File "E:\anaconda\envs\logitech\lib\site-packages\ray\rllib\agents\trainer.py", line 648, in train
    raise e
  File "E:\anaconda\envs\logitech\lib\site-packages\ray\rllib\agents\trainer.py", line 637, in train
    result = Trainable.train(self)
  File "E:\anaconda\envs\logitech\lib\site-packages\ray\tune\trainable.py", line 237, in train
    result = self.step()
  File "E:\anaconda\envs\logitech\lib\site-packages\ray\rllib\agents\trainer_template.py", line 193, in step
    res = next(self.train_exec_impl)
  File "E:\anaconda\envs\logitech\lib\site-packages\ray\util\iter.py", line 756, in __next__
    return next(self.built_iterator)
  File "E:\anaconda\envs\logitech\lib\site-packages\ray\util\iter.py", line 783, in apply_foreach
    for item in it:
  File "E:\anaconda\envs\logitech\lib\site-packages\ray\util\iter.py", line 843, in apply_filter
    for item in it:
  File "E:\anaconda\envs\logitech\lib\site-packages\ray\util\iter.py", line 843, in apply_filter
    for item in it:
  File "E:\anaconda\envs\logitech\lib\site-packages\ray\util\iter.py", line 783, in apply_foreach
    for item in it:
  File "E:\anaconda\envs\logitech\lib\site-packages\ray\util\iter.py", line 843, in apply_filter
    for item in it:
  File "E:\anaconda\envs\logitech\lib\site-packages\ray\util\iter.py", line 1075, in build_union
    item = next(it)
  File "E:\anaconda\envs\logitech\lib\site-packages\ray\util\iter.py", line 756, in __next__
    return next(self.built_iterator)
  File "E:\anaconda\envs\logitech\lib\site-packages\ray\util\iter.py", line 783, in apply_foreach
    for item in it:
  File "E:\anaconda\envs\logitech\lib\site-packages\ray\util\iter.py", line 783, in apply_foreach
    for item in it:
  File "E:\anaconda\envs\logitech\lib\site-packages\ray\util\iter.py", line 783, in apply_foreach
    for item in it:
  [Previous line repeated 1 more time]
  File "E:\anaconda\envs\logitech\lib\site-packages\ray\util\iter.py", line 471, in base_iterator
    yield ray.get(futures, timeout=timeout)
  File "E:\anaconda\envs\logitech\lib\site-packages\ray\_private\client_mode_hook.py", line 82, in wrapper
    return func(*args, **kwargs)
  File "E:\anaconda\envs\logitech\lib\site-packages\ray\worker.py", line 1623, in get
    raise value
ray.exceptions.RayActorError: The actor died unexpectedly before finishing this task.

